<?xml version="1.0" encoding="utf-8"?>
<!-- This URDF was automatically created by SolidWorks to URDF Exporter! Originally created by Stephen Brawner (brawner@gmail.com) 
     Commit Version: 1.6.0-4-g7f85cfe  Build Version: 1.6.7995.38578
     For more information, please see http://wiki.ros.org/sw_urdf_exporter -->
<robot
  name="elegoo_simu">
  <link
    name="base_link">
    <inertial>
      <origin
        xyz="-0.000113663942252208 0.0016356087293449 -0.0213439740529758"
        rpy="0 0 0" />
      <mass
        value="0.320481422655543" />
      <inertia
        ixx="0.00084861505736386"
        ixy="2.97152629807315E-07"
        ixz="3.4555913160792E-07"
        iyy="0.000200725740731641"
        iyz="3.92026930988534E-09"
        izz="0.00103876752693472" />
    </inertial>
    <visual>
      <origin
        xyz="0 0 0"
        rpy="0 0 0" />
      <geometry>
        <mesh
          filename="package://elegoo_simu/meshes/base_link.STL" />
      </geometry>
      <material
        name="">
        <color
          rgba="0.101960784313725 0.101960784313725 0.101960784313725 1" />
      </material>
    </visual>
    <collision>
      <origin
        xyz="0 0 0"
        rpy="0 0 0" />
      <geometry>
        <mesh
          filename="package://elegoo_simu/meshes/base_link.STL" />
      </geometry>
    </collision>
  </link>
  <link
    name="fr_motor_Link">
    <inertial>
      <origin
        xyz="0.000404669277169013 -0.0112499995993381 0.0202439168825699"
        rpy="0 0 0" />
      <mass
        value="0.00854876685458474" />
      <inertia
        ixx="1.17165891905496E-06"
        ixy="-4.71279785478066E-15"
        ixz="-7.83815378361147E-09"
        iyy="1.07002331783213E-06"
        iyz="2.3792883709663E-15"
        izz="6.48599680422981E-07" />
    </inertial>
    <visual>
      <origin
        xyz="0 0 0"
        rpy="0 0 0" />
      <geometry>
        <mesh
          filename="package://elegoo_simu/meshes/fr_motor_Link.STL" />
      </geometry>
      <material
        name="">
        <color
          rgba="1 1 1 1" />
      </material>
    </visual>
    <collision>
      <origin
        xyz="0 0 0"
        rpy="0 0 0" />
      <geometry>
        <mesh
          filename="package://elegoo_simu/meshes/fr_motor_Link.STL" />
      </geometry>
    </collision>
  </link>
  <joint
    name="fr_motor_joint"
    type="fixed">
    <origin
      xyz="0.0371499999999999 -0.0493500000160009 -0.0197000000000017"
      rpy="1.5707963267949 0 0" />
    <parent
      link="base_link" />
    <child
      link="fr_motor_Link" />
    <axis
      xyz="0 0 0" />
  </joint>
  <link
    name="fr_wheel_link">
    <inertial>
      <origin
        xyz="0.00812098210358325 -2.61234610332561E-11 -8.04612418359163E-11"
        rpy="0 0 0" />
      <mass
        value="0.306109899457103" />
      <inertia
        ixx="0.000221397987094039"
        ixy="-9.62581541173754E-14"
        ixz="-3.12944022472771E-15"
        iyy="0.000120221604288152"
        iyz="7.50069762248007E-10"
        izz="0.000120221932097438" />
    </inertial>
    <visual>
      <origin
        xyz="0 0 0"
        rpy="0 0 0" />
      <geometry>
        <mesh
          filename="package://elegoo_simu/meshes/fr_wheel_link.STL" />
      </geometry>
      <material
        name="">
        <color
          rgba="0.650980392156863 0.619607843137255 0.588235294117647 1" />
      </material>
    </visual>
    <collision>
      <origin
        xyz="0 0 0"
        rpy="0 0 0" />
      <geometry>
        <mesh
          filename="package://elegoo_simu/meshes/fr_wheel_link.STL" />
      </geometry>
    </collision>
  </link>
  <joint
    name="fr_wheel_joint"
    type="continuous">
    <origin
      xyz="0.0159000000000001 -0.0112499999999997 -0.0079499999999967"
      rpy="0 0 0" />
    <parent
      link="fr_motor_Link" />
    <child
      link="fr_wheel_link" />
    <axis
      xyz="-1 0 0" />
  </joint>
  <link
    name="br_motor_link">
    <inertial>
      <origin
        xyz="-0.0154953307228312 -4.00661698263249E-10 -0.0281939168825704"
        rpy="0 0 0" />
      <mass
        value="0.00854876685458474" />
      <inertia
        ixx="1.17165891905496E-06"
        ixy="4.71279774467707E-15"
        ixz="7.83815378361441E-09"
        iyy="1.07002331783213E-06"
        iyz="2.37928747643173E-15"
        izz="6.48599680422981E-07" />
    </inertial>
    <visual>
      <origin
        xyz="0 0 0"
        rpy="0 0 0" />
      <geometry>
        <mesh
          filename="package://elegoo_simu/meshes/br_motor_link.STL" />
      </geometry>
      <material
        name="">
        <color
          rgba="1 1 1 1" />
      </material>
    </visual>
    <collision>
      <origin
        xyz="0 0 0"
        rpy="0 0 0" />
      <geometry>
        <mesh
          filename="package://elegoo_simu/meshes/br_motor_link.STL" />
      </geometry>
    </collision>
  </link>
  <joint
    name="br_motor_joint"
    type="fixed">
    <origin
      xyz="0.0530500000000004 0.0404000000159994 -0.0309499999999987"
      rpy="1.5707963267949 0 0" />
    <parent
      link="base_link" />
    <child
      link="br_motor_link" />
    <axis
      xyz="0 0 0" />
  </joint>
  <link
    name="br_wheel_link">
    <inertial>
      <origin
        xyz="0.00812098233727378 2.80416386291837E-10 2.0403299882954E-10"
        rpy="0 0 0" />
      <mass
        value="0.306109913185571" />
      <inertia
        ixx="0.00022139798772043"
        ixy="-1.25012312894634E-13"
        ixz="-1.34374232556409E-13"
        iyy="0.000120221402395312"
        iyz="-6.74940995961599E-10"
        izz="0.000120222134866692" />
    </inertial>
    <visual>
      <origin
        xyz="0 0 0"
        rpy="0 0 0" />
      <geometry>
        <mesh
          filename="package://elegoo_simu/meshes/br_wheel_link.STL" />
      </geometry>
      <material
        name="">
        <color
          rgba="0.650980392156863 0.619607843137255 0.588235294117647 1" />
      </material>
    </visual>
    <collision>
      <origin
        xyz="0 0 0"
        rpy="0 0 0" />
      <geometry>
        <mesh
          filename="package://elegoo_simu/meshes/br_wheel_link.STL" />
      </geometry>
    </collision>
  </link>
  <joint
    name="br_wheel_joint"
    type="continuous">
    <origin
      xyz="0 0 0"
      rpy="0 0 0" />
    <parent
      link="br_motor_link" />
    <child
      link="br_wheel_link" />
    <axis
      xyz="-1 0 0" />
  </joint>
  <link
    name="fl_motor_link">
    <inertial>
      <origin
        xyz="-0.000404669277169013 -0.0112500004006633 0.0202439168825699"
        rpy="0 0 0" />
      <mass
        value="0.00854876685458474" />
      <inertia
        ixx="1.17165891905496E-06"
        ixy="-4.71279823894848E-15"
        ixz="7.83815378361184E-09"
        iyy="1.07002331783213E-06"
        iyz="-2.37925942310969E-15"
        izz="6.48599680422981E-07" />
    </inertial>
    <visual>
      <origin
        xyz="0 0 0"
        rpy="0 0 0" />
      <geometry>
        <mesh
          filename="package://elegoo_simu/meshes/fl_motor_link.STL" />
      </geometry>
      <material
        name="">
        <color
          rgba="1 1 1 1" />
      </material>
    </visual>
    <collision>
      <origin
        xyz="0 0 0"
        rpy="0 0 0" />
      <geometry>
        <mesh
          filename="package://elegoo_simu/meshes/fl_motor_link.STL" />
      </geometry>
    </collision>
  </link>
  <joint
    name="fl_motor_link"
    type="fixed">
    <origin
      xyz="-0.0371499999999999 -0.0493500000160009 -0.0197000000000017"
      rpy="1.5707963267949 0 0" />
    <parent
      link="base_link" />
    <child
      link="fl_motor_link" />
    <axis
      xyz="0 0 0" />
  </joint>
  <link
    name="fl_wheel_link">
    <inertial>
      <origin
        xyz="-0.00812098210216261 8.01126751742709E-11 -1.09581989315988E-10"
        rpy="0 0 0" />
      <mass
        value="0.306109899373842" />
      <inertia
        ixx="0.000221397987089165"
        ixy="-1.63115246544794E-14"
        ixz="1.8153812927422E-14"
        iyy="0.000120221604257845"
        iyz="7.49836921709807E-10"
        izz="0.000120221932121374" />
    </inertial>
    <visual>
      <origin
        xyz="0 0 0"
        rpy="0 0 0" />
      <geometry>
        <mesh
          filename="package://elegoo_simu/meshes/fl_wheel_link.STL" />
      </geometry>
      <material
        name="">
        <color
          rgba="0.650980392156863 0.619607843137255 0.588235294117647 1" />
      </material>
    </visual>
    <collision>
      <origin
        xyz="0 0 0"
        rpy="0 0 0" />
      <geometry>
        <mesh
          filename="package://elegoo_simu/meshes/fl_wheel_link.STL" />
      </geometry>
    </collision>
  </link>
  <joint
    name="fl_wheel_joint"
    type="continuous">
    <origin
      xyz="-0.0159000000000001 -0.0112499999999997 -0.00794999999999667"
      rpy="0 0 0" />
    <parent
      link="fl_motor_link" />
    <child
      link="fl_wheel_link" />
    <axis
      xyz="-1 0 0" />
  </joint>
  <link
    name="bl_motor_link">
    <inertial>
      <origin
        xyz="-0.000404669277169097 -0.0112499995993367 -0.0202439168825707"
        rpy="0 0 0" />
      <mass
        value="0.00854876685458473" />
      <inertia
        ixx="1.17165891905496E-06"
        ixy="4.71279827228387E-15"
        ixz="-7.83815378361442E-09"
        iyy="1.07002331783213E-06"
        iyz="-2.3792601179567E-15"
        izz="6.48599680422981E-07" />
    </inertial>
    <visual>
      <origin
        xyz="0 0 0"
        rpy="0 0 0" />
      <geometry>
        <mesh
          filename="package://elegoo_simu/meshes/bl_motor_link.STL" />
      </geometry>
      <material
        name="">
        <color
          rgba="1 1 1 1" />
      </material>
    </visual>
    <collision>
      <origin
        xyz="0 0 0"
        rpy="0 0 0" />
      <geometry>
        <mesh
          filename="package://elegoo_simu/meshes/bl_motor_link.STL" />
      </geometry>
    </collision>
  </link>
  <joint
    name="bl_motor_joint"
    type="fixed">
    <origin
      xyz="-0.0371500000000002 0.0483500000159991 -0.0196999999999984"
      rpy="1.5707963267949 0 0" />
    <parent
      link="base_link" />
    <child
      link="bl_motor_link" />
    <axis
      xyz="0 0 0" />
  </joint>
  <link
    name="bl_wheel_link">
    <inertial>
      <origin
        xyz="-0.00812098209818358 -8.86754315809757E-11 1.58697679997211E-10"
        rpy="0 0 0" />
      <mass
        value="0.306109899141489" />
      <inertia
        ixx="0.000221397987078634"
        ixy="-2.46875736421512E-14"
        ixz="2.1832869905823E-14"
        iyy="0.000120221402158807"
        iyz="-6.74917916683295E-10"
        izz="0.000120222134205591" />
    </inertial>
    <visual>
      <origin
        xyz="0 0 0"
        rpy="0 0 0" />
      <geometry>
        <mesh
          filename="package://elegoo_simu/meshes/bl_wheel_link.STL" />
      </geometry>
      <material
        name="">
        <color
          rgba="0.650980392156863 0.619607843137255 0.588235294117647 1" />
      </material>
    </visual>
    <collision>
      <origin
        xyz="0 0 0"
        rpy="0 0 0" />
      <geometry>
        <mesh
          filename="package://elegoo_simu/meshes/bl_wheel_link.STL" />
      </geometry>
    </collision>
  </link>
  <joint
    name="bl_wheel_joint"
    type="continuous">
    <origin
      xyz="-0.0159000000000005 -0.0112500000000003 0.00794999999999974"
      rpy="0 0 0" />
    <parent
      link="bl_motor_link" />
    <child
      link="bl_wheel_link" />
    <axis
      xyz="-1 0 0" />
  </joint>
  <link
    name="servo_Link">
    <inertial>
      <origin
        xyz="0.00607283375162547 -0.00183789515247874 -0.000357176173858123"
        rpy="0 0 0" />
      <mass
        value="0.00718760563331449" />
      <inertia
        ixx="7.10250592751377E-07"
        ixy="5.72081013428577E-19"
        ixz="4.96492179667808E-14"
        iyy="4.32928194351315E-07"
        iyz="2.78915203316387E-08"
        izz="4.52034743523462E-07" />
    </inertial>
    <visual>
      <origin
        xyz="0 0 0"
        rpy="0 0 0" />
      <geometry>
        <mesh
          filename="package://elegoo_simu/meshes/servo_Link.STL" />
      </geometry>
      <material
        name="">
        <color
          rgba="0.501960784313725 0.501960784313725 0.501960784313725 1" />
      </material>
    </visual>
    <collision>
      <origin
        xyz="0 0 0"
        rpy="0 0 0" />
      <geometry>
        <mesh
          filename="package://elegoo_simu/meshes/servo_Link.STL" />
      </geometry>
    </collision>
  </link>
  <joint
    name="servo_joint"
    type="fixed">
    <origin
      xyz="-0.00602783382563871 -0.0887500000000001 0.0026547190729892"
      rpy="1.5707963267949 0 0" />
    <parent
      link="base_link" />
    <child
      link="servo_Link" />
    <axis
      xyz="0 0 0" />
  </joint>
  <link
    name="ultrasonic_link">
    <inertial>
      <origin
        xyz="0.000186378632557201 0.0180611896657809 0.00944681751031289"
        rpy="0 0 0" />
      <mass
        value="0.0095427452850795" />
      <inertia
        ixx="6.46398900589765E-07"
        ixy="-1.3157370995658E-09"
        ixz="1.7516152650556E-08"
        iyy="1.01797208530448E-06"
        iyz="-6.66885345101064E-08"
        izz="1.53387834735778E-06" />
    </inertial>
    <visual>
      <origin
        xyz="0 0 0"
        rpy="0 0 0" />
      <geometry>
        <mesh
          filename="package://elegoo_simu/meshes/ultrasonic_link.STL" />
      </geometry>
      <material
        name="">
        <color
          rgba="0.101960784313725 0.101960784313725 0.101960784313725 1" />
      </material>
    </visual>
    <collision>
      <origin
        xyz="0 0 0"
        rpy="0 0 0" />
      <geometry>
        <mesh
          filename="package://elegoo_simu/meshes/ultrasonic_link.STL" />
      </geometry>
    </collision>
  </link>
  <joint
    name="ultrasonic_joint"
    type="continuous">
    <origin
      xyz="0.00607283375163871 0.0164052809270108 -0.00579000000000005"
      rpy="0 0 0" />
    <parent
      link="servo_Link" />
    <child
      link="ultrasonic_link" />
    <axis
      xyz="0 1 0" />
  </joint>
  <link
    name="track_sensor_Link">
    <inertial>
      <origin
        xyz="0.000477308888217252 -0.000414812003878431 0.000256174286212774"
        rpy="0 0 0" />
      <mass
        value="0.00804782748410787" />
      <inertia
        ixx="4.70841197895188E-07"
        ixy="1.33881254865877E-09"
        ixz="-1.36270485213359E-08"
        iyy="1.67017735061089E-06"
        iyz="-9.08429358767128E-09"
        izz="1.23708186999385E-06" />
    </inertial>
    <visual>
      <origin
        xyz="0 0 0"
        rpy="0 0 0" />
      <geometry>
        <mesh
          filename="package://elegoo_simu/meshes/track_sensor_Link.STL" />
      </geometry>
      <material
        name="">
        <color
          rgba="0.643137254901961 0.615686274509804 0.6 1" />
      </material>
    </visual>
    <collision>
      <origin
        xyz="0 0 0"
        rpy="0 0 0" />
      <geometry>
        <mesh
          filename="package://elegoo_simu/meshes/track_sensor_Link.STL" />
      </geometry>
    </collision>
  </link>
  <joint
    name="track_sensor_joint"
    type="fixed">
    <origin
      xyz="-0.000287508725744888 -0.0943526002392224 -0.0521"
      rpy="1.5707963267949 0 0" />
    <parent
      link="base_link" />
    <child
      link="track_sensor_Link" />
    <axis
      xyz="0 0 0" />
  </joint>
  <link
    name="esp32_link">
    <inertial>
      <origin
        xyz="0.00680502314224933 0.00010258100727624 4.24504957637246E-05"
        rpy="0 0 0" />
      <mass
        value="0.00453801750708847" />
      <inertia
        ixx="2.38865919200289E-07"
        ixy="-2.35601527156661E-08"
        ixz="-8.82344231728213E-11"
        iyy="1.05984189174445E-06"
        iyz="5.32794164930141E-11"
        izz="8.46807257014312E-07" />
    </inertial>
    <visual>
      <origin
        xyz="0 0 0"
        rpy="0 0 0" />
      <geometry>
        <mesh
          filename="package://elegoo_simu/meshes/esp32_link.STL" />
      </geometry>
      <material
        name="">
        <color
          rgba="0.796078431372549 0.823529411764706 0.937254901960784 1" />
      </material>
    </visual>
    <collision>
      <origin
        xyz="0 0 0"
        rpy="0 0 0" />
      <geometry>
        <mesh
          filename="package://elegoo_simu/meshes/esp32_link.STL" />
      </geometry>
    </collision>
  </link>
  <joint
    name="esp32_joint"
    type="fixed">
    <origin
      xyz="-0.00614078181180603 0.0311604748959537 0.0042"
      rpy="1.5707963267949 0 0" />
    <parent
      link="base_link" />
    <child
      link="esp32_link" />
    <axis
      xyz="0 0 0" />
  </joint>
  <link
    name="imu_link">
    <inertial>
      <origin
        xyz="-7.04863640918355E-06 0 -0.000486156769983702"
        rpy="0 0 0" />
      <mass
        value="0.000311849337348909" />
      <inertia
        ixx="9.99884491287168E-09"
        ixy="-1.05590212555396E-24"
        ixz="-4.41597075204144E-28"
        iyy="6.35705073390977E-09"
        iyz="1.48379477199371E-28"
        izz="1.63048460077501E-08" />
    </inertial>
    <visual>
      <origin
        xyz="0 0 0"
        rpy="0 0 0" />
      <geometry>
        <mesh
          filename="package://elegoo_simu/meshes/imu_link.STL" />
      </geometry>
      <material
        name="">
        <color
          rgba="0.666666666666667 0.698039215686274 0.768627450980392 1" />
      </material>
    </visual>
    <collision>
      <origin
        xyz="0 0 0"
        rpy="0 0 0" />
      <geometry>
        <mesh
          filename="package://elegoo_simu/meshes/imu_link.STL" />
      </geometry>
    </collision>
  </link>
  <joint
    name="imu_joint"
    type="fixed">
    <origin
      xyz="-0.00171649060501221 -0.0317500000000002 -0.0412"
      rpy="0 0 0" />
    <parent
      link="base_link" />
    <child
      link="imu_link" />
    <axis
      xyz="0 0 0" />
  </joint>
  <link
    name="l298_link">
    <inertial>
      <origin
        xyz="-0.000545161612490729 -0.00684487389585518 0.0147975578460123"
        rpy="0 0 0" />
      <mass
        value="0.0258928081974277" />
      <inertia
        ixx="1.92543190581059E-06"
        ixy="2.96876853910725E-10"
        ixz="2.98302033340927E-22"
        iyy="3.09891750369211E-06"
        iyz="1.39491593493273E-07"
        izz="2.17577602367061E-06" />
    </inertial>
    <visual>
      <origin
        xyz="0 0 0"
        rpy="0 0 0" />
      <geometry>
        <mesh
          filename="package://elegoo_simu/meshes/l298_link.STL" />
      </geometry>
      <material
        name="">
        <color
          rgba="0.250980392156863 0.250980392156863 0.250980392156863 1" />
      </material>
    </visual>
    <collision>
      <origin
        xyz="0 0 0"
        rpy="0 0 0" />
      <geometry>
        <mesh
          filename="package://elegoo_simu/meshes/l298_link.STL" />
      </geometry>
    </collision>
  </link>
  <joint
    name="l298_joint"
    type="fixed">
    <origin
      xyz="0 0.0149499999999998 -0.0259358457987049"
      rpy="1.5707963267949 0 0" />
    <parent
      link="base_link" />
    <child
      link="l298_link" />
    <axis
      xyz="0 0 0" />
  </joint>
</robot>