<?xml version="1.0" encoding="utf-8"?>
<!-- This URDF was automatically created by SolidWorks to URDF Exporter! Originally created by Stephen Brawner (brawner@gmail.com) 
     Commit Version: 1.6.0-4-g7f85cfe  Build Version: 1.6.7995.38578
     For more information, please see http://wiki.ros.org/sw_urdf_exporter -->
<robot
  name="ros_elegoo">
  <link
    name="base_link">
    <inertial>
      <origin
        xyz="0.000224132390614626 0.00290276379414369 -0.00369642997928919"
        rpy="0 0 0" />
      <mass
        value="0.447412932101708" />
      <inertia
        ixx="0.00126460381310963"
        ixy="5.87066191544574E-07"
        ixz="3.45559131610179E-07"
        iyy="0.000291395875351319"
        iyz="3.92026930506241E-09"
        izz="0.00153766677575398" />
    </inertial>
    <visual>
      <origin
        xyz="0 0 0"
        rpy="0 0 0" />
      <geometry>
        <mesh
          filename="package://ros_elegoo/meshes/base_link.STL" />
      </geometry>
      <material
        name="">
        <color
          rgba="0.101960784313725 0.101960784313725 0.101960784313725 1" />
      </material>
    </visual>
    <collision>
      <origin
        xyz="0 0 0"
        rpy="0 0 0" />
      <geometry>
        <mesh
          filename="package://ros_elegoo/meshes/base_link.STL" />
      </geometry>
    </collision>
  </link>
  <link
    name="fr_motor_Link">
    <inertial>
      <origin
        xyz="0.000404669277168999 -0.0112499995993381 0.0202439168825699"
        rpy="0 0 0" />
      <mass
        value="0.00854876685458473" />
      <inertia
        ixx="1.17165891905496E-06"
        ixy="-4.71279788627504E-15"
        ixz="-7.83815378361146E-09"
        iyy="1.07002331783213E-06"
        iyz="2.37928840757079E-15"
        izz="6.48599680422981E-07" />
    </inertial>
    <visual>
      <origin
        xyz="0 0 0"
        rpy="0 0 0" />
      <geometry>
        <mesh
          filename="package://ros_elegoo/meshes/fr_motor_Link.STL" />
      </geometry>
      <material
        name="">
        <color
          rgba="1 1 1 1" />
      </material>
    </visual>
    <collision>
      <origin
        xyz="0 0 0"
        rpy="0 0 0" />
      <geometry>
        <mesh
          filename="package://ros_elegoo/meshes/fr_motor_Link.STL" />
      </geometry>
    </collision>
  </link>
  <joint
    name="fr_motor_joint"
    type="fixed">
    <origin
      xyz="0.0371499999999999 -0.0493500000160009 -0.0197000000000017"
      rpy="1.5707963267949 0 0" />
    <parent
      link="base_link" />
    <child
      link="fr_motor_Link" />
    <axis
      xyz="0 0 0" />
  </joint>
  <link
    name="fr_wheel_link">
    <inertial>
      <origin
        xyz="0.00812098210358325 -2.61234592985327E-11 -8.0461262652598E-11"
        rpy="0 0 0" />
      <mass
        value="0.306109899457103" />
      <inertia
        ixx="0.000221397987094038"
        ixy="-9.62581530330337E-14"
        ixz="-3.12943948853337E-15"
        iyy="0.000120221604288152"
        iyz="7.50069762249322E-10"
        izz="0.000120221932097438" />
    </inertial>
    <visual>
      <origin
        xyz="0 0 0"
        rpy="0 0 0" />
      <geometry>
        <mesh
          filename="package://ros_elegoo/meshes/fr_wheel_link.STL" />
      </geometry>
      <material
        name="">
        <color
          rgba="0.650980392156863 0.619607843137255 0.588235294117647 1" />
      </material>
    </visual>
    <collision>
      <origin
        xyz="0 0 0"
        rpy="0 0 0" />
      <geometry>
        <mesh
          filename="package://ros_elegoo/meshes/fr_wheel_link.STL" />
      </geometry>
    </collision>
  </link>
  <joint
    name="fr_wheel_joint"
    type="continuous">
    <origin
      xyz="0.0159000000000001 -0.0112499999999997 -0.0079499999999967"
      rpy="0 0 0" />
    <parent
      link="fr_motor_Link" />
    <child
      link="fr_wheel_link" />
    <axis
      xyz="-1 0 0" />
  </joint>
  <link
    name="br_motor_link">
    <inertial>
      <origin
        xyz="-0.0154953307228312 -4.00661726018825E-10 -0.0281939168825704"
        rpy="0 0 0" />
      <mass
        value="0.00854876685458473" />
      <inertia
        ixx="1.17165891905496E-06"
        ixy="4.71279757480978E-15"
        ixz="7.83815378361429E-09"
        iyy="1.07002331783213E-06"
        iyz="2.37928748694362E-15"
        izz="6.48599680422981E-07" />
    </inertial>
    <visual>
      <origin
        xyz="0 0 0"
        rpy="0 0 0" />
      <geometry>
        <mesh
          filename="package://ros_elegoo/meshes/br_motor_link.STL" />
      </geometry>
      <material
        name="">
        <color
          rgba="1 1 1 1" />
      </material>
    </visual>
    <collision>
      <origin
        xyz="0 0 0"
        rpy="0 0 0" />
      <geometry>
        <mesh
          filename="package://ros_elegoo/meshes/br_motor_link.STL" />
      </geometry>
    </collision>
  </link>
  <joint
    name="br_motor_joint"
    type="fixed">
    <origin
      xyz="0.0530500000000004 0.0404000000159994 -0.0309499999999987"
      rpy="1.5707963267949 0 0" />
    <parent
      link="base_link" />
    <child
      link="br_motor_link" />
    <axis
      xyz="0 0 0" />
  </joint>
  <link
    name="br_wheel_link">
    <inertial>
      <origin
        xyz="0.00812098233727378 2.80416362005709E-10 2.04032991890646E-10"
        rpy="0 0 0" />
      <mass
        value="0.306109913185571" />
      <inertia
        ixx="0.00022139798772043"
        ixy="-1.25012311228873E-13"
        ixz="-1.34374232607138E-13"
        iyy="0.000120221402395312"
        iyz="-6.74940995969859E-10"
        izz="0.000120222134866692" />
    </inertial>
    <visual>
      <origin
        xyz="0 0 0"
        rpy="0 0 0" />
      <geometry>
        <mesh
          filename="package://ros_elegoo/meshes/br_wheel_link.STL" />
      </geometry>
      <material
        name="">
        <color
          rgba="0.650980392156863 0.619607843137255 0.588235294117647 1" />
      </material>
    </visual>
    <collision>
      <origin
        xyz="0 0 0"
        rpy="0 0 0" />
      <geometry>
        <mesh
          filename="package://ros_elegoo/meshes/br_wheel_link.STL" />
      </geometry>
    </collision>
  </link>
  <joint
    name="br_wheel_joint"
    type="continuous">
    <origin
      xyz="0 0 0"
      rpy="0 0 0" />
    <parent
      link="br_motor_link" />
    <child
      link="br_wheel_link" />
    <axis
      xyz="-1 0 0" />
  </joint>
  <link
    name="fl_motor_link">
    <inertial>
      <origin
        xyz="-0.000404669277169145 -0.0112500004006633 0.0202439168825699"
        rpy="0 0 0" />
      <mass
        value="0.00854876685458474" />
      <inertia
        ixx="1.17165891905496E-06"
        ixy="-4.71279827793423E-15"
        ixz="7.83815378361175E-09"
        iyy="1.07002331783213E-06"
        iyz="-2.37925934840732E-15"
        izz="6.48599680422981E-07" />
    </inertial>
    <visual>
      <origin
        xyz="0 0 0"
        rpy="0 0 0" />
      <geometry>
        <mesh
          filename="package://ros_elegoo/meshes/fl_motor_link.STL" />
      </geometry>
      <material
        name="">
        <color
          rgba="1 1 1 1" />
      </material>
    </visual>
    <collision>
      <origin
        xyz="0 0 0"
        rpy="0 0 0" />
      <geometry>
        <mesh
          filename="package://ros_elegoo/meshes/fl_motor_link.STL" />
      </geometry>
    </collision>
  </link>
  <joint
    name="fl_motor_link"
    type="fixed">
    <origin
      xyz="-0.0371499999999999 -0.0493500000160009 -0.0197000000000017"
      rpy="1.5707963267949 0 0" />
    <parent
      link="base_link" />
    <child
      link="fl_motor_link" />
    <axis
      xyz="0 0 0" />
  </joint>
  <link
    name="fl_wheel_link">
    <inertial>
      <origin
        xyz="-0.00812098210216262 8.01126161936727E-11 -1.095819754382E-10"
        rpy="0 0 0" />
      <mass
        value="0.306109899373842" />
      <inertia
        ixx="0.000221397987089165"
        ixy="-1.6311524816855E-14"
        ixz="1.81538116845508E-14"
        iyy="0.000120221604257845"
        iyz="7.49836921707819E-10"
        izz="0.000120221932121374" />
    </inertial>
    <visual>
      <origin
        xyz="0 0 0"
        rpy="0 0 0" />
      <geometry>
        <mesh
          filename="package://ros_elegoo/meshes/fl_wheel_link.STL" />
      </geometry>
      <material
        name="">
        <color
          rgba="0.650980392156863 0.619607843137255 0.588235294117647 1" />
      </material>
    </visual>
    <collision>
      <origin
        xyz="0 0 0"
        rpy="0 0 0" />
      <geometry>
        <mesh
          filename="package://ros_elegoo/meshes/fl_wheel_link.STL" />
      </geometry>
    </collision>
  </link>
  <joint
    name="fl_wheel_joint"
    type="continuous">
    <origin
      xyz="-0.0159000000000001 -0.0112499999999997 -0.00794999999999667"
      rpy="0 0 0" />
    <parent
      link="fl_motor_link" />
    <child
      link="fl_wheel_link" />
    <axis
      xyz="-1 0 0" />
  </joint>
  <link
    name="bl_motor_link">
    <inertial>
      <origin
        xyz="-0.000404669277169104 -0.0112499995993368 -0.0202439168825706"
        rpy="0 0 0" />
      <mass
        value="0.00854876685458473" />
      <inertia
        ixx="1.17165891905496E-06"
        ixy="4.71279830195046E-15"
        ixz="-7.8381537836144E-09"
        iyy="1.07002331783213E-06"
        iyz="-2.37926029159227E-15"
        izz="6.48599680422981E-07" />
    </inertial>
    <visual>
      <origin
        xyz="0 0 0"
        rpy="0 0 0" />
      <geometry>
        <mesh
          filename="package://ros_elegoo/meshes/bl_motor_link.STL" />
      </geometry>
      <material
        name="">
        <color
          rgba="1 1 1 1" />
      </material>
    </visual>
    <collision>
      <origin
        xyz="0 0 0"
        rpy="0 0 0" />
      <geometry>
        <mesh
          filename="package://ros_elegoo/meshes/bl_motor_link.STL" />
      </geometry>
    </collision>
  </link>
  <joint
    name="bl_motor_joint"
    type="fixed">
    <origin
      xyz="-0.0371500000000002 0.0483500000159991 -0.0196999999999984"
      rpy="1.5707963267949 0 0" />
    <parent
      link="base_link" />
    <child
      link="bl_motor_link" />
    <axis
      xyz="0 0 0" />
  </joint>
  <link
    name="bl_wheel_link">
    <inertial>
      <origin
        xyz="-0.00812098209818358 -8.86754576018278E-11 1.58697659180529E-10"
        rpy="0 0 0" />
      <mass
        value="0.306109899141489" />
      <inertia
        ixx="0.000221397987078634"
        ixy="-2.46875751691076E-14"
        ixz="2.18328724270767E-14"
        iyy="0.000120221402158807"
        iyz="-6.74917916691226E-10"
        izz="0.000120222134205591" />
    </inertial>
    <visual>
      <origin
        xyz="0 0 0"
        rpy="0 0 0" />
      <geometry>
        <mesh
          filename="package://ros_elegoo/meshes/bl_wheel_link.STL" />
      </geometry>
      <material
        name="">
        <color
          rgba="0.650980392156863 0.619607843137255 0.588235294117647 1" />
      </material>
    </visual>
    <collision>
      <origin
        xyz="0 0 0"
        rpy="0 0 0" />
      <geometry>
        <mesh
          filename="package://ros_elegoo/meshes/bl_wheel_link.STL" />
      </geometry>
    </collision>
  </link>
  <joint
    name="bl_wheel_joint"
    type="continuous">
    <origin
      xyz="-0.0159000000000005 -0.0112500000000003 0.00794999999999974"
      rpy="0 0 0" />
    <parent
      link="bl_motor_link" />
    <child
      link="bl_wheel_link" />
    <axis
      xyz="-1 0 0" />
  </joint>
  <link
    name="track_sensor_Link">
    <inertial>
      <origin
        xyz="0.000477308888217251 -0.000414812003878435 0.000256174286212787"
        rpy="0 0 0" />
      <mass
        value="0.00804782748410787" />
      <inertia
        ixx="4.70841197895188E-07"
        ixy="1.33881254865878E-09"
        ixz="-1.3627048521336E-08"
        iyy="1.67017735061089E-06"
        iyz="-9.08429358767128E-09"
        izz="1.23708186999385E-06" />
    </inertial>
    <visual>
      <origin
        xyz="0 0 0"
        rpy="0 0 0" />
      <geometry>
        <mesh
          filename="package://ros_elegoo/meshes/track_sensor_Link.STL" />
      </geometry>
      <material
        name="">
        <color
          rgba="0.643137254901961 0.615686274509804 0.6 1" />
      </material>
    </visual>
    <collision>
      <origin
        xyz="0 0 0"
        rpy="0 0 0" />
      <geometry>
        <mesh
          filename="package://ros_elegoo/meshes/track_sensor_Link.STL" />
      </geometry>
    </collision>
  </link>
  <joint
    name="track_sensor_joint"
    type="fixed">
    <origin
      xyz="-0.000287508725744888 -0.0943526002392224 -0.0521"
      rpy="1.5707963267949 0 0" />
    <parent
      link="base_link" />
    <child
      link="track_sensor_Link" />
    <axis
      xyz="0 0 0" />
  </joint>
  <link
    name="esp32_link">
    <inertial>
      <origin
        xyz="0.00680502314224933 0.000102581007276233 4.24504957637264E-05"
        rpy="0 0 0" />
      <mass
        value="0.00453801750708847" />
      <inertia
        ixx="2.38865919200289E-07"
        ixy="-2.35601527156661E-08"
        ixz="-8.82344231728073E-11"
        iyy="1.05984189174445E-06"
        iyz="5.32794164930131E-11"
        izz="8.46807257014312E-07" />
    </inertial>
    <visual>
      <origin
        xyz="0 0 0"
        rpy="0 0 0" />
      <geometry>
        <mesh
          filename="package://ros_elegoo/meshes/esp32_link.STL" />
      </geometry>
      <material
        name="">
        <color
          rgba="0.796078431372549 0.823529411764706 0.937254901960784 1" />
      </material>
    </visual>
    <collision>
      <origin
        xyz="0 0 0"
        rpy="0 0 0" />
      <geometry>
        <mesh
          filename="package://ros_elegoo/meshes/esp32_link.STL" />
      </geometry>
    </collision>
  </link>
  <joint
    name="esp32_joint"
    type="fixed">
    <origin
      xyz="-0.00614078181180599 -0.012931966185866 0.0042"
      rpy="1.5707963267949 0 0" />
    <parent
      link="base_link" />
    <child
      link="esp32_link" />
    <axis
      xyz="0 0 0" />
  </joint>
  <link
    name="imu_link">
    <inertial>
      <origin
        xyz="-7.04863640918442E-06 0 -0.000486156769983702"
        rpy="0 0 0" />
      <mass
        value="0.000311849337348909" />
      <inertia
        ixx="9.99884491287168E-09"
        ixy="-1.04384067270755E-24"
        ixz="-2.70572638152192E-28"
        iyy="6.35705073390977E-09"
        iyz="1.48379477199371E-28"
        izz="1.63048460077501E-08" />
    </inertial>
    <visual>
      <origin
        xyz="0 0 0"
        rpy="0 0 0" />
      <geometry>
        <mesh
          filename="package://ros_elegoo/meshes/imu_link.STL" />
      </geometry>
      <material
        name="">
        <color
          rgba="0.666666666666667 0.698039215686274 0.768627450980392 1" />
      </material>
    </visual>
    <collision>
      <origin
        xyz="0 0 0"
        rpy="0 0 0" />
      <geometry>
        <mesh
          filename="package://ros_elegoo/meshes/imu_link.STL" />
      </geometry>
    </collision>
  </link>
  <joint
    name="imu_joint"
    type="fixed">
    <origin
      xyz="-0.00171649060501221 -0.0317500000000002 -0.0412"
      rpy="0 0 0" />
    <parent
      link="base_link" />
    <child
      link="imu_link" />
    <axis
      xyz="0 0 0" />
  </joint>
  <link
    name="l298_link">
    <inertial>
      <origin
        xyz="-0.000545161612490729 -0.00684487389585517 0.0147975578460123"
        rpy="0 0 0" />
      <mass
        value="0.0258928081974277" />
      <inertia
        ixx="1.92543190581059E-06"
        ixy="2.9687685391076E-10"
        ixz="3.56627158154896E-22"
        iyy="3.09891750369211E-06"
        iyz="1.39491593493273E-07"
        izz="2.17577602367061E-06" />
    </inertial>
    <visual>
      <origin
        xyz="0 0 0"
        rpy="0 0 0" />
      <geometry>
        <mesh
          filename="package://ros_elegoo/meshes/l298_link.STL" />
      </geometry>
      <material
        name="">
        <color
          rgba="0.250980392156863 0.250980392156863 0.250980392156863 1" />
      </material>
    </visual>
    <collision>
      <origin
        xyz="0 0 0"
        rpy="0 0 0" />
      <geometry>
        <mesh
          filename="package://ros_elegoo/meshes/l298_link.STL" />
      </geometry>
    </collision>
  </link>
  <joint
    name="l298_joint"
    type="fixed">
    <origin
      xyz="0 0.0149499999999998 -0.0259358457987049"
      rpy="1.5707963267949 0 0" />
    <parent
      link="base_link" />
    <child
      link="l298_link" />
    <axis
      xyz="0 0 0" />
  </joint>
</robot>